2020/12/28 02:51:09 : customers_errors 1: Traceback (most recent call last):
  File "/var/www/python/cartmigration/controllers/migration.py", line 1113, in migration
    after_import = fn_after_import(id_desc, convert_data, main, ext)
  File "/var/www/python/cartmigration/models/cart/woocommerce.py", line 4122, in after_customer_import
    'description': convert[''],
KeyError: ''

2020/12/28 02:51:09 : customers_errors 3: Traceback (most recent call last):
  File "/var/www/python/cartmigration/controllers/migration.py", line 1113, in migration
    after_import = fn_after_import(id_desc, convert_data, main, ext)
  File "/var/www/python/cartmigration/models/cart/woocommerce.py", line 4122, in after_customer_import
    'description': convert[''],
KeyError: ''

